Workbook

Sheet Hoja1
A1: REVISION DE TALON DE CHEQUES
A2: MAESTRO
A3: RFC | B3: DEMO850312AB1 | C3: NOMBRE | D3: Demo SA
A4: QNA TALON | C4: 09-2026 | D4: FECHA TALON
A5: INGRESOS | D5: DEDUCCIONES
A6: =+Hoja2!A6 | B6: 8500 | C6: 14500 | D6: DESCUENTOS | E6: 12500
A7: =+Hoja2!A7 | B7: 4200 | D7: SALDO | E7: 2000
A8: =+Hoja2!A8 | B8: 1800 | D8: TOTAL PARA VENTA 70% | E8: 10150
A9: =+Hoja2!A9 | B9: 0
A10: =+Hoja2!A10 | B10: 0 | D10: SALDO AL 70% | E10: -2350
A11: =+Hoja2!A11 | B11: 0 | D11: SALDO MAS ABONOS AL 70%
A12: =+Hoja2!A12 | B12: 0 | D12: -2350
A13: =+Hoja2!A13 | B13: 0 | D13: SALDO MAS ABONO A TERMINAR AL 100
A14: =+Hoja2!A14 | B14: 0
A15: =+Hoja2!A15 | B15: 0 | D15: 2000
A16: DC TALON | B16: 0 | C16: DC SISTEMA | D16: 0 | E16: =+B16-D16
A17: VENDEDOR | B17: RECUPERACIÓN (Abonos a Liquidar) | D17: VENTA(entrante o en relcmacion)
B19: FOLIO | C19: SALDO | D19: FOLIO | E19: SALDO
C20: 0 | E20: 0
C21: 0 | E21: 0
C22: 0 | E22: 0
C23: 0 | E23: 0
B24: Total a Recuperar | D24: Total a VENDER
B25: 0 | D25: 0
B27: SALDO AL 70 | D27: SALDO AL 100
B28: -2350 | D28: 2000
A30: REVISION DEL CLIENTE
A31: PROMOTOR | B31: Ana Torres
A32: NOMBRE: | B32: Demo SA
A33: RFC: | B33: DEMO850312AB1
A34: LIQUIDEZ | B34: 2000
A35: QNA | B35: 09-2026
A36: COMENTARIO | B36: Se realizó la revisión del talón correspondiente al cliente: Cliente: Demo SA RFC: DEMO850312AB1 Resultado de la revisión: Tiene liquidez de $2,000.00.
A40: FECHA | B40: 18/06/2026
A41: LIQUIDEZ DEL TALÓN | D41: 2000
A42: APOYO ADICIONAL | D42: 0
A43: TOTAL SALDO LIBERADO | D43: 0
A44: TOTAL SOLO OBSERVADO | D44: 0
A45: MONTO PROGRAMADO | D45: 0
A46: LIQUIDEZ ANTES LIBERACIÓN | D46: 2000
...

Sheet Hoja2
A1: CONCEPTOS DE INGRESOS PARA CALCULAR LA CAPACIDAD DE PAGO | J1: D=DESCUENTOS
A2: DEFICINION DE DESCUENTOS | C2: 07= SUELDO | D2: A,Q=QUINQUENIO | F2: E9=ASIGNACION DOCENTE | I2: E3,E4=ARRAIGO | K2: CP=COMPENSASION PROV
C3: CT= COMPENSASION TEM
A5: CODIGO | B5: ABONOS | C5: CODIGO | D5: ABONOS | E5: CODIGO | F5: ABONOS | G5: CODIGO | H5: ABONOS | I5: CODIGO | J5: ABONOS | K5: CODIGO | L5: ABONOS | M5: CODIGO | N5: ABONOS | O5: CODIGO | P5: ABONOS
A6: E4 | C6: =+A6 | E6: =+C6 | G6: =+E6 | I6: =+G6 | K6: =+I6 | M6: =+K6 | O6: =+M6
A7: E3 | C7: =+A7 | E7: =+C7 | G7: =+E7 | I7: =+G7 | K7: =+I7 | M7: =+K7 | O7: =+M7
A8: Q | C8: =+A8 | E8: =+C8 | G8: =+E8 | I8: =+G8 | K8: =+I8 | M8: =+K8 | O8: =+M8
A9: CP | C9: =+A9 | E9: =+C9 | G9: =+E9 | I9: =+G9 | K9: =+I9 | M9: =+K9 | O9: =+M9
A10: 7 | C10: =+A10 | E10: =+C10 | G10: =+E10 | I10: =+G10 | K10: =+I10 | M10: =+K10 | O10: =+M10
A11: CT | C11: =+A11 | E11: =+C11 | G11: =+E11 | I11: =+G11 | K11: =+I11 | M11: =+K11 | O11: =+M11
A12: 7B | C12: =+A12 | E12: =+C12 | G12: =+E12 | I12: =+G12 | K12: =+I12 | M12: =+K12 | O12: =+M12
A13: E9 | C13: =+A13 | E13: =+C13 | G13: =+E13 | I13: =+G13 | K13: =+I13 | M13: =+K13 | O13: =+M13
A14: SG | C14: =+A14 | E14: =+C14 | G14: =+E14 | I14: =+G14 | K14: =+I14 | M14: =+K14 | O14: =+M14
A15: O1 | C15: =+A15 | E15: =+C15 | G15: =+E15 | I15: =+G15 | K15: =+I15 | M15: =+K15 | O15: =+M15
A16: D | C16: =+A16 | E16: =+C16 | G16: =+E16 | I16: =+G16 | K16: =+I16 | M16: =+K16 | O16: =+M16
A17: DC | C17: =+A17 | E17: =+C17 | G17: =+E17 | I17: =+G17 | K17: =+I17 | M17: =+K17 | O17: =+M17
A18: total | D18: =+SUM(D6:D15)-D16 | F18: =+SUM(F6:F15)-F16 | H18: =+SUM(H6:H15)-H16 | J18: =+SUM(J6:J15)-J16 | L18: =+SUM(L6:L15)-L16 | N18: =+SUM(N6:N15)-N16 | P18: =+SUM(P6:P15)-P16
A19: TOTAL
A20: =+A6 | B20: =+B6+D6+F6+J6+H6+L6+N6+P6
A21: =+A7 | B21: =+B7+D7+F7+J7+H7+L7+N7+P7
A22: =+A8 | B22: =+B8+D8+F8+J8+H8+L8+N8+P8
A23: =+A9 | B23: =+B9+D9+F9+J9+H9+L9+N9+P9
A24: =+A10 | B24: =+B10+D10+F10+J10+H10+L10+N10+P10
A25: =+A11 | B25: =+B11+D11+F11+J11+H11+L11+N11+P11
A26: =+A12 | B26: =+B12+D12+F12+J12+H12+L12+N12+P12
A27: =+A13 | B27: =+B13+D13+F13+J13+H13+L13+N13+P13
A28: =+A14 | B28: =+B14+D14+F14+J14+H14+L14+N14+P14
A29: =+A15 | B29: =+B15+D15+F15+J15+H15+L15+N15+P15
A30: =+A16 | B30: =+B16+D16+F16+J16+H16+L16+N16+P16
A31: =+A17 | B31: =+B17+D17+F17+J17+H17+L17+N17+P17

Sheet Hoja3
B1: 28254.2
A2: =+B1-B2 | B2: 12263.92

Sheet CUENTAS_TERMINADAS
A1: fecha_revision | B1: cliente | C1: rfc | D1: vendedor | E1: qna_revision | F1: qna_termina | G1: saldo_liberado | H1: sumar_a_liquidez | I1: observacion
